Workbook

Sheet Assumptions
A1: myFamiPedia — Cost Model Assumptions
A2: All usage figures below are PER FAMILY (aggregate across all active members), not per person, unless labeled 'per user'.
A4: Exchange rate
A5: EUR per USD | B5: 0.92 | D5: Illustrative — update to the current rate before relying on this model
A7: Cloud / API pricing (USD)
A8: Component | B8: Rate (USD) | C8: Per | D8: Source
A9: R2 storage | B9: 0.015 | C9: GB-month | D9: Cloudflare R2 pricing, developers.cloudflare.com/r2/pricing (fetched Jul 2026)
A10: R2 Class A operations | B10: 4.5 | C10: 1,000,000 ops | D10: Cloudflare R2 pricing (fetched Jul 2026)
A11: R2 Class B operations | B11: 0.36 | C11: 1,000,000 ops | D11: Cloudflare R2 pricing (fetched Jul 2026)
A12: Voyage multimodal-3.5 — text | B12: 0.12 | C12: 1,000,000 tokens | D12: docs.voyageai.com/docs/pricing (fetched Jul 2026)
A13: Voyage multimodal-3.5 — image | B13: 0.6 | C13: 1,000,000,000 pixels | D13: docs.voyageai.com/docs/pricing (fetched Jul 2026)
A14: OpenAI Whisper transcription | B14: 0.006 | C14: minute | D14: OpenAI API pricing, per-minute rate (fetched Jul 2026)
A15: ElevenLabs TTS (Multilingual v2/v3) | B15: 0.1 | C15: 1,000 characters | D15: elevenlabs.io/pricing/api, pay-as-you-go rate (fetched Jul 2026)
A16: AWS Rekognition DetectFaces (Group 2, tier 1) | B16: 0.001 | C16: image | D16: aws.amazon.com/rekognition/pricing, first 1M images/month tier (fetched Jul 2026)
A17: AWS Rekognition SearchFacesByImage (Group 1, tier 1) | B17: 0.001 | C17: image | D17: aws.amazon.com/rekognition/pricing, first 1M images/month tier (fetched Jul 2026)
A18: AWS Rekognition face vector storage | B18: 1e-05 | C18: face-vector per month | D18: aws.amazon.com/rekognition/pricing (fetched Jul 2026)
A19: DeepL translation (marginal) | B19: 25 | C19: 1,000,000 characters | D19: DeepL API Pro plan, no volume discount (fetched Jul 2026)
A20: DeepL API Pro base fee | B20: 5.49 | C20: month (fixed) | D20: DeepL API Pro plan base fee (fetched Jul 2026)
A21: OVHcloud VPS-2 2027 | B21: 8.5 | C21: month per instance | D21: OVHcloud VPS pricing; matches the 4 vCore / 8GB / 75GB VPS already in use (fetched Jul 2026)
A23: Photo volume — bottom-up per-user driver, with storage cross-check
A24: Photo share of storage growth | B24: 0.85 | E24: Used only in the storage-derived cross-check row below, not in the primary cost driver
A25: Avg photo file size as stored on R2 | B25: 4 | E25: MB — used only in the storage-derived cross-check row below
A27: Per-family usage assumptions (illustrative — adjust freely)
A28: Component | B28: Year 1 | C28: Year 5 | D28: Year 10 | E28: Unit / basis
A29: Family size (active members) | B29: 20 | C29: 20 | D29: 20 | E29: people — from product doc
A30: Storage per family (cumulative) | B30: 12 | C30: 55 | D30: 110 | E30: GB — from product doc, section 10
A31: Photos uploaded per active user per month | B31: 20 | C31: 20 | D31: 20 | E31: PRIMARY DRIVER — per your estimate. Edit per year if engagement changes over time.
A32: New photos processed per month (family total) | B32: =B31*B29 -> 400 | C32: =C31*C29 -> 400 | D32: =D31*D29 -> 400 | E32: Formula: photos/user/month x family size. This is what feeds Rekognition and Voyage-image cost below.
A33: cross-check: photos/month implied by storage growth | B33: =$B$30*1024*$B$24/$B$25/12 -> 217.6 | C33: =(C30-B30)*1024*$B$24/$B$25/48 -> 194.93333 | D33: =(D30-C30)*1024*$B$24/$B$25/60 -> 199.46667 | E33: Reference only, does not feed cost formulas. If this diverges a lot from the row above, the storage figure, avg photo size, or per-user estimate is off — not all photos taken are necessarily kept/stored at full size.
A34: Avg pixels per photo (post-compression) | B34: 2000000 | C34: 2000000 | D34: 2000000 | E34: pixels — for Voyage image-embedding cost
A35: Voice minutes transcribed per month | B35: 15 | C35: 10 | D35: 5 | E35: minutes/month — anchored to Section 3 session cadence
A36: New memories created per month (text/voice) | B36: 30 | C36: 20 | D36: 12 | E36: memories/month — question-stream answers + interview transcripts + text notes
A37: Avg tokens per memory | B37: 120 | C37: 120 | D37: 120 | E37: tokens
A38: AI-narration characters synthesized per month | B38: 500 | C38: 2000 | D38: 4000 | E38: characters/month — grows as more of the archive relies on AI synthesis
A39: Translation characters per month | B39: 1000 | C39: 1000 | D39: 1000 | E39: characters/month — rough blended average
A40: Active face vectors enrolled | B40: 20 | C40: 20 | D40: 20 | E40: faces — only active/consented members are enrolled
A41: R2 Class A ops per month (writes) | B41: =(B32+B36)*1.1 -> 473 | C41: =(C32+C36)*1.1 -> 462 | D41: =(D32+D36)*1.1 -> 453.2 | E41: DERIVED: (photos + memories) x 1.1 buffer for multipart/retries
A42: R2 Class B ops per month (reads) | B42: 600 | C42: 500 | D42: 400 | E42: ops/month — family browsing activity, independent estimate
A44: Scale / shared-cost assumptions
A45: Representative family count (headline per-family view) | B45: 500 | E45: families — used to allocate VPS + DeepL base fee per family below
...

Sheet Per-Family Monthly Cost
A1: myFamiPedia — Per-Family Monthly Cost (EUR)
A3: Cost component | B3: Year 1 (€/mo) | C3: Year 5 (€/mo) | D3: Year 10 (€/mo)
A4: R2 storage | B4: =Assumptions!$B$30*Assumptions!$B$9*Assumptions!$B$5*(1+Assumptions!$B$50)^Assumptions!$B$49 -> 0.14904 | C4: =Assumptions!$C$30*Assumptions!$B$9*Assumptions!$B$5*(1+Assumptions!$B$50)^Assumptions!$C$49 -> 0.44818191 | D4: =Assumptions!$D$30*Assumptions!$B$9*Assumptions!$B$5*(1+Assumptions!$B$50)^Assumptions!$D$49 -> 0.52929387
A5: R2 operations (Class A + Class B) | B5: =(Assumptions!$B$41*Assumptions!$B$10/1000000+Assumptions!$B$42*Assumptions!$B$11/1000000)*Assumptions!$B$5*(1+Assumptions!$B$50)^Assumptions!$B$49 -> 0.001941246 | C5: =(Assumptions!$C$41*Assumptions!$B$10/1000000+Assumptions!$C$42*Assumptions!$B$11/1000000)*Assumptions!$B$5*(1+Assumptions!$B$50)^Assumptions!$C$49 -> 0.0012272036 | D5: =(Assumptions!$D$41*Assumptions!$B$10/1000000+Assumptions!$D$42*Assumptions!$B$11/1000000)*Assumptions!$B$5*(1+Assumptions!$B$50)^Assumptions!$D$49 -> 0.00070040015
A6: Whisper transcription | B6: =Assumptions!$B$35*Assumptions!$B$14*Assumptions!$B$5*(1+Assumptions!$B$50)^Assumptions!$B$49 -> 0.07452 | C6: =Assumptions!$C$35*Assumptions!$B$14*Assumptions!$B$5*(1+Assumptions!$B$50)^Assumptions!$C$49 -> 0.032595048 | D6: =Assumptions!$D$35*Assumptions!$B$14*Assumptions!$B$5*(1+Assumptions!$B$50)^Assumptions!$D$49 -> 0.0096235249
A7: ElevenLabs TTS (AI narration) | B7: =Assumptions!$B$38/1000*Assumptions!$B$15*Assumptions!$B$5*(1+Assumptions!$B$50)^Assumptions!$B$49 -> 0.0414 | C7: =Assumptions!$C$38/1000*Assumptions!$B$15*Assumptions!$B$5*(1+Assumptions!$B$50)^Assumptions!$C$49 -> 0.10865016 | D7: =Assumptions!$D$38/1000*Assumptions!$B$15*Assumptions!$B$5*(1+Assumptions!$B$50)^Assumptions!$D$49 -> 0.12831367
A8: Voyage embeddings — text (memories) | B8: =(Assumptions!$B$36*Assumptions!$B$37)/1000000*Assumptions!$B$12*Assumptions!$B$5*(1+Assumptions!$B$50)^Assumptions!$B$49 -> 0.000357696 | C8: =(Assumptions!$C$36*Assumptions!$C$37)/1000000*Assumptions!$B$12*Assumptions!$B$5*(1+Assumptions!$B$50)^Assumptions!$C$49 -> 0.00015645623 | D8: =(Assumptions!$D$36*Assumptions!$D$37)/1000000*Assumptions!$B$12*Assumptions!$B$5*(1+Assumptions!$B$50)^Assumptions!$D$49 -> 5.5431504e-05
A9: Voyage embeddings — image (photos) | B9: =(Assumptions!$B$32*Assumptions!$B$34)/1000000000*Assumptions!$B$13*Assumptions!$B$5*(1+Assumptions!$B$50)^Assumptions!$B$49 -> 0.39744 | C9: =(Assumptions!$C$32*Assumptions!$C$34)/1000000000*Assumptions!$B$13*Assumptions!$B$5*(1+Assumptions!$B$50)^Assumptions!$C$49 -> 0.26076038 | D9: =(Assumptions!$D$32*Assumptions!$D$34)/1000000000*Assumptions!$B$13*Assumptions!$B$5*(1+Assumptions!$B$50)^Assumptions!$D$49 -> 0.1539764
A10: Rekognition DetectFaces | B10: =Assumptions!$B$32*Assumptions!$B$16*Assumptions!$B$5*(1+Assumptions!$B$50)^Assumptions!$B$49 -> 0.3312 | C10: =Assumptions!$C$32*Assumptions!$B$16*Assumptions!$B$5*(1+Assumptions!$B$50)^Assumptions!$C$49 -> 0.21730032 | D10: =Assumptions!$D$32*Assumptions!$B$16*Assumptions!$B$5*(1+Assumptions!$B$50)^Assumptions!$D$49 -> 0.12831367
A11: Rekognition SearchFacesByImage | B11: =Assumptions!$B$32*Assumptions!$B$17*Assumptions!$B$5*(1+Assumptions!$B$50)^Assumptions!$B$49 -> 0.3312 | C11: =Assumptions!$C$32*Assumptions!$B$17*Assumptions!$B$5*(1+Assumptions!$B$50)^Assumptions!$C$49 -> 0.21730032 | D11: =Assumptions!$D$32*Assumptions!$B$17*Assumptions!$B$5*(1+Assumptions!$B$50)^Assumptions!$D$49 -> 0.12831367
A12: Rekognition face vector storage | B12: =Assumptions!$B$40*Assumptions!$B$18*Assumptions!$B$5*(1+Assumptions!$B$50)^Assumptions!$B$49 -> 0.0001656 | C12: =Assumptions!$C$40*Assumptions!$B$18*Assumptions!$B$5*(1+Assumptions!$B$50)^Assumptions!$C$49 -> 0.00010865016 | D12: =Assumptions!$D$40*Assumptions!$B$18*Assumptions!$B$5*(1+Assumptions!$B$50)^Assumptions!$D$49 -> 6.4156833e-05
A13: DeepL translation (marginal) | B13: =Assumptions!$B$39/1000000*Assumptions!$B$19*Assumptions!$B$5*(1+Assumptions!$B$50)^Assumptions!$B$49 -> 0.0207 | C13: =Assumptions!$C$39/1000000*Assumptions!$B$19*Assumptions!$B$5*(1+Assumptions!$B$50)^Assumptions!$C$49 -> 0.01358127 | D13: =Assumptions!$D$39/1000000*Assumptions!$B$19*Assumptions!$B$5*(1+Assumptions!$B$50)^Assumptions!$D$49 -> 0.0080196041
A14: Subtotal — variable cost per family | B14: =SUM(B4:B13) -> 1.3479645 | C14: =SUM(C4:C13) -> 1.2998617 | D14: =SUM(D4:D13) -> 1.0866744
A16: VPS cost per family (shared, at representative family count) | B16: =INDEX('Scale Scenarios'!$D:$D,MATCH(Assumptions!$B$45,'Scale Scenarios'!$A:$A,0))*(1+Assumptions!$B$50)^Assumptions!$B$49 -> 0.0083117372 | C16: =INDEX('Scale Scenarios'!$D:$D,MATCH(Assumptions!$B$45,'Scale Scenarios'!$A:$A,0))*(1+Assumptions!$B$50)^Assumptions!$C$49 -> 0.0054533308 | D16: =INDEX('Scale Scenarios'!$D:$D,MATCH(Assumptions!$B$45,'Scale Scenarios'!$A:$A,0))*(1+Assumptions!$B$50)^Assumptions!$D$49 -> 0.0032201373
A17: DeepL base fee per family (shared, at representative family count) | B17: =INDEX('Scale Scenarios'!$E:$E,MATCH(Assumptions!$B$45,'Scale Scenarios'!$A:$A,0))*(1+Assumptions!$B$50)^Assumptions!$B$49 -> 0.0053684044 | C17: =INDEX('Scale Scenarios'!$E:$E,MATCH(Assumptions!$B$45,'Scale Scenarios'!$A:$A,0))*(1+Assumptions!$B$50)^Assumptions!$C$49 -> 0.0035222101 | D17: =INDEX('Scale Scenarios'!$E:$E,MATCH(Assumptions!$B$45,'Scale Scenarios'!$A:$A,0))*(1+Assumptions!$B$50)^Assumptions!$D$49 -> 0.0020798299
A18: Subtotal — fixed/shared cost per family | B18: =SUM(B16:B17) -> 0.013680142 | C18: =SUM(C16:C17) -> 0.0089755409 | D18: =SUM(D16:D17) -> 0.0052999672
A20: Total infra cost per family per month | B20: =B14+B18 -> 1.3616447 | C20: =C14+C18 -> 1.3088373 | D20: =D14+D18 -> 1.0919744
A21: Biggest single expense (label) | B21: =INDEX($A$4:$A$13,MATCH(MAX(B4:B13),B4:B13,0)) -> Voyage embeddings — image (photos) | C21: =INDEX($A$4:$A$13,MATCH(MAX(C4:C13),C4:C13,0)) -> R2 storage | D21: =INDEX($A$4:$A$13,MATCH(MAX(D4:D13),D4:D13,0)) -> R2 storage
A23: Revenue — monthly plan (avg of €12–15) | B23: =13.5*(1+Assumptions!$B$51)^Assumptions!$B$49 -> 13.905 | C23: =13.5*(1+Assumptions!$B$51)^Assumptions!$C$49 -> 15.6502 | D23: =13.5*(1+Assumptions!$B$51)^Assumptions!$D$49 -> 18.142871
A24: Revenue — annual plan (avg of €99–120, ÷12) | B24: =(109.5/12)*(1+Assumptions!$B$51)^Assumptions!$B$49 -> 9.39875 | C24: =(109.5/12)*(1+Assumptions!$B$51)^Assumptions!$C$49 -> 10.578376 | D24: =(109.5/12)*(1+Assumptions!$B$51)^Assumptions!$D$49 -> 12.263237
A26: Gross margin € (monthly plan) | B26: =B23-B20 -> 12.543355 | C26: =C23-C20 -> 14.341363 | D26: =D23-D20 -> 17.050897
A27: Gross margin % (monthly plan) | B27: =B26/B23 -> 0.90207518 | C27: =C26/C23 -> 0.91636929 | D27: =D26/D23 -> 0.93981248
A29: Gross margin € (annual plan) | B29: =B24-B20 -> 8.0371053 | C29: =C24-C20 -> 9.2695387 | D29: =D24-D20 -> 11.171263
A30: Gross margin % (annual plan) | B30: =B29/B24 -> 0.85512492 | C30: =C29/C24 -> 0.87627238 | D30: =D29/D24 -> 0.91095546
A32: Target gross margin (per product doc, midpoint of 75-80%) | B32: 0.775 | C32: 0.775 | D32: 0.775
A33: Monthly plan vs. target (pp) | B33: =B27-B32 -> 0.12707518 | C33: =C27-C32 -> 0.14136929 | D33: =D27-D32 -> 0.16481248
A34: Annual plan vs. target (pp) | B34: =B30-B32 -> 0.080124917 | C34: =C30-C32 -> 0.10127238 | D34: =D30-D32 -> 0.13595546

Sheet Scale Scenarios
A1: myFamiPedia — Scale Scenarios (EUR, Year 5 usage basis)
A2: Variable cost per family uses the Year 5 usage assumptions as a representative mid-life family; fixed cost (VPS + DeepL base) and revenue both apply the Year 5 deflation/inflation factor from the Assumptions sheet, for consistency with the Year 5 basis stated above.
A4: Families | B4: VPS instances needed | C4: VPS cost total (€/mo) | D4: VPS €/family | E4: DeepL base €/family | F4: Fixed €/family | G4: Variable €/family (Y5) | H4: Total €/family | I4: Revenue €/family (monthly plan) | J4: Margin %
A5: 50 | B5: =CEILING(A5/Assumptions!$B$46,1) -> 1 | C5: =B5*Assumptions!$B$21*Assumptions!$B$5*(1+Assumptions!$B$50)^Assumptions!$C$49 -> 4.6176318 | D5: =C5/A5 -> 0.092352636 | E5: =Assumptions!$B$20*Assumptions!$B$5/A5*(1+Assumptions!$B$50)^Assumptions!$C$49 -> 0.059648938 | F5: =D5+E5 -> 0.15200157 | G5: ='Per-Family Monthly Cost'!$C$14 -> 1.2998617 | H5: =F5+G5 -> 1.4518633 | I5: ='Per-Family Monthly Cost'!$C$23 -> 15.6502 | J5: =(I5-H5)/I5 -> 0.90723037
A6: 100 | B6: =CEILING(A6/Assumptions!$B$46,1) -> 1 | C6: =B6*Assumptions!$B$21*Assumptions!$B$5*(1+Assumptions!$B$50)^Assumptions!$C$49 -> 4.6176318 | D6: =C6/A6 -> 0.046176318 | E6: =Assumptions!$B$20*Assumptions!$B$5/A6*(1+Assumptions!$B$50)^Assumptions!$C$49 -> 0.029824469 | F6: =D6+E6 -> 0.076000787 | G6: ='Per-Family Monthly Cost'!$C$14 -> 1.2998617 | H6: =F6+G6 -> 1.3758625 | I6: ='Per-Family Monthly Cost'!$C$23 -> 15.6502 | J6: =(I6-H6)/I6 -> 0.91208659
A7: 500 | B7: =CEILING(A7/Assumptions!$B$46,1) -> 1 | C7: =B7*Assumptions!$B$21*Assumptions!$B$5*(1+Assumptions!$B$50)^Assumptions!$C$49 -> 4.6176318 | D7: =C7/A7 -> 0.0092352636 | E7: =Assumptions!$B$20*Assumptions!$B$5/A7*(1+Assumptions!$B$50)^Assumptions!$C$49 -> 0.0059648938 | F7: =D7+E7 -> 0.015200157 | G7: ='Per-Family Monthly Cost'!$C$14 -> 1.2998617 | H7: =F7+G7 -> 1.3150619 | I7: ='Per-Family Monthly Cost'!$C$23 -> 15.6502 | J7: =(I7-H7)/I7 -> 0.91597156
A8: 1000 | B8: =CEILING(A8/Assumptions!$B$46,1) -> 1 | C8: =B8*Assumptions!$B$21*Assumptions!$B$5*(1+Assumptions!$B$50)^Assumptions!$C$49 -> 4.6176318 | D8: =C8/A8 -> 0.0046176318 | E8: =Assumptions!$B$20*Assumptions!$B$5/A8*(1+Assumptions!$B$50)^Assumptions!$C$49 -> 0.0029824469 | F8: =D8+E8 -> 0.0076000787 | G8: ='Per-Family Monthly Cost'!$C$14 -> 1.2998617 | H8: =F8+G8 -> 1.3074618 | I8: ='Per-Family Monthly Cost'!$C$23 -> 15.6502 | J8: =(I8-H8)/I8 -> 0.91645718
A9: 5000 | B9: =CEILING(A9/Assumptions!$B$46,1) -> 3 | C9: =B9*Assumptions!$B$21*Assumptions!$B$5*(1+Assumptions!$B$50)^Assumptions!$C$49 -> 13.852895 | D9: =C9/A9 -> 0.0027705791 | E9: =Assumptions!$B$20*Assumptions!$B$5/A9*(1+Assumptions!$B$50)^Assumptions!$C$49 -> 0.00059648938 | F9: =D9+E9 -> 0.0033670685 | G9: ='Per-Family Monthly Cost'!$C$14 -> 1.2998617 | H9: =F9+G9 -> 1.3032288 | I9: ='Per-Family Monthly Cost'!$C$23 -> 15.6502 | J9: =(I9-H9)/I9 -> 0.91672766
A10: 10000 | B10: =CEILING(A10/Assumptions!$B$46,1) -> 5 | C10: =B10*Assumptions!$B$21*Assumptions!$B$5*(1+Assumptions!$B$50)^Assumptions!$C$49 -> 23.088159 | D10: =C10/A10 -> 0.0023088159 | E10: =Assumptions!$B$20*Assumptions!$B$5/A10*(1+Assumptions!$B$50)^Assumptions!$C$49 -> 0.00029824469 | F10: =D10+E10 -> 0.0026070606 | G10: ='Per-Family Monthly Cost'!$C$14 -> 1.2998617 | H10: =F10+G10 -> 1.3024688 | I10: ='Per-Family Monthly Cost'!$C$23 -> 15.6502 | J10: =(I10-H10)/I10 -> 0.91677622

Sheet Notes & Sources
A1: myFamiPedia — Notes, Sources & Caveats
A3: Pricing sources
A4: Cloudflare R2 | B4: https://developers.cloudflare.com/r2/pricing/ — fetched July 2026
A5: Voyage AI (voyage-multimodal-3.5) | B5: https://docs.voyageai.com/docs/pricing — fetched July 2026
A6: OpenAI Whisper | B6: Per-minute rate as used in the product handover doc, confirmed via web search July 2026
A7: ElevenLabs | B7: https://elevenlabs.io/pricing/api — pay-as-you-go rate, fetched July 2026
A8: AWS Rekognition | B8: https://aws.amazon.com/rekognition/pricing/ — fetched July 2026
A9: DeepL | B9: DeepL API Pro plan pricing, fetched July 2026
A10: OVHcloud VPS-2 2027 | B10: Matches the VPS already in use (4 vCore / 8GB RAM / 75GB), fetched July 2026
A12: Key assumptions and simplifications — read before relying on this model
A13: Per-family, not per-person, except the photo driver | B13: Every usage figure is a whole-family aggregate except 'Photos uploaded per active user per month,' which is deliberately per-user and multiplied by family size — this was changed based on direct feedback that per-user is the more intuitive way to reason about photo volume.
A14: Photo volume history | B14: V1 used an independent flat family-level guess (20-40/month) — too low against the doc's own storage figures. V2 derived photo count from storage growth instead. V3 (this version) switched the primary driver to a per-user rate (20 photos/user/month x family size = 400/month), per direct input, with the storage-derived figure kept as a visible cross-check row rather than deleted.
A15: Storage cross-check gap | B15: At 20 photos/user/month, the model implies more monthly photo volume than the doc's stated storage growth (12/55/110GB) would suggest at 4MB/photo. Either the storage figures undercount, the average stored photo is smaller than 4MB (compression, thumbnailing), or not every photo taken is retained. This is surfaced, not silently reconciled — see the cross-check row in Assumptions.
A16: EUR/USD rate | B16: Fixed illustrative rate (Assumptions!B5). Update to the live rate; every cost in this model scales linearly with it.
A17: Remaining usage figures are still illustrative | B17: Voice minutes/month, memories/month, AI-narration characters/month, and translation characters/month are estimates, not measured data.
A18: Rekognition tier | B18: Modeled at the first-tier (under 1M images/month platform-wide) rate. Volume discounts at real scale would lower this — model is conservative (overstates cost) at high platform scale.
A19: ElevenLabs billing model | B19: Modeled at the pay-as-you-go per-character rate; a paid plan may be required to unlock professional voice cloning, not separately modeled.
A20: VPS capacity assumption | B20: One VPS-2 2027 instance assumed to serve up to 2,000 active families — heavy compute runs on external APIs, not the VPS.
A21: Revenue | B21: €13.50/month and €9.13/month (€99-120/year ÷12) are both blue inputs on the Per-Family Monthly Cost sheet.
A22: What this model does NOT include | B22: Staff/dev time, payment processing fees, support tooling, marketing/CAC, myMigo-shared overhead. Strictly per-family cloud/API infrastructure cost.
A24: Cost deflation & price inflation (new)
A25: Why | B25: The first three versions applied flat July-2026 pricing across Year 1/5/10, which implicitly assumes cloud/AI unit costs never change and subscription pricing never changes for a decade — both unrealistic in opposite directions.
A26: Cost deflation | B26: Assumptions!B50 (-10%/year default) compounds against every cost line and against VPS/DeepL base fees, using (1+rate)^years — 'years' being how far each column sits from today (1/5/10), not a family-tenure clock. Illustrative, not a forecast; set to 0% to disable.
A27: Price inflation | B27: Assumptions!B51 (+3%/year default) compounds against both revenue lines the same way. Set to 0% to disable.
A28: Net effect | B28: These two levers pull margin in opposite directions from the previous (static-price) version: costs shrink over the decade instead of just growing with usage, and revenue grows instead of staying flat — both improve Year 10 margin relative to the prior version. Check the Per-Family Monthly Cost sheet's Year 10 margin lines to see the current net result with the default -10%/+3% assumptions.
